distributed.nanny - INFO -         Start Nanny at: 'tcp://10.120.40.89:38905'
distributed.worker - INFO -       Start worker at:   tcp://10.120.40.89:34894
distributed.worker - INFO -          Listening to:   tcp://10.120.40.89:34894
distributed.worker - INFO -          dashboard at:         10.120.40.89:38579
distributed.worker - INFO - Waiting to connect to:   tcp://10.120.43.21:37853
distributed.worker - INFO - -------------------------------------------------
distributed.worker - INFO -               Threads:                          1
distributed.worker - INFO -                Memory:                    8.00 GB
distributed.worker - INFO -       Local Directory: /home/ad/alberta/dask-worker-space/worker-spzq0ces
distributed.worker - INFO - -------------------------------------------------
distributed.worker - INFO -         Registered to:   tcp://10.120.43.21:37853
distributed.worker - INFO - -------------------------------------------------
distributed.core - INFO - Starting established connection
distributed.core - INFO - Event loop was unresponsive in Worker for 3.41s.  This is often caused by long-running GIL-holding functions or moving large chunks of data. This can cause timeouts and instability.
distributed.core - INFO - Event loop was unresponsive in Worker for 7.82s.  This is often caused by long-running GIL-holding functions or moving large chunks of data. This can cause timeouts and instability.
distributed.core - INFO - Event loop was unresponsive in Worker for 5.65s.  This is often caused by long-running GIL-holding functions or moving large chunks of data. This can cause timeouts and instability.
distributed.core - INFO - Event loop was unresponsive in Worker for 8.22s.  This is often caused by long-running GIL-holding functions or moving large chunks of data. This can cause timeouts and instability.
distributed.core - INFO - Event loop was unresponsive in Worker for 3.56s.  This is often caused by long-running GIL-holding functions or moving large chunks of data. This can cause timeouts and instability.
distributed.worker - INFO - Can't find dependencies for key ('mean_combine-partial-ea26edd6ea215345d2db27703f9d4c15', 2122, 0, 0)
distributed.worker - INFO - Can't find dependencies for key ('mean_combine-partial-ea26edd6ea215345d2db27703f9d4c15', 2122, 0, 0)
distributed.worker - INFO - Dependent not found: ('mean_chunk-5c95da98151b93916264b226a1972684', 8488, 0, 0) 0 .  Asking scheduler
distributed.core - INFO - Event loop was unresponsive in Worker for 4.75s.  This is often caused by long-running GIL-holding functions or moving large chunks of data. This can cause timeouts and instability.
distributed.core - INFO - Event loop was unresponsive in Worker for 8.00s.  This is often caused by long-running GIL-holding functions or moving large chunks of data. This can cause timeouts and instability.
distributed.core - INFO - Event loop was unresponsive in Worker for 5.50s.  This is often caused by long-running GIL-holding functions or moving large chunks of data. This can cause timeouts and instability.
distributed.core - INFO - Event loop was unresponsive in Worker for 6.62s.  This is often caused by long-running GIL-holding functions or moving large chunks of data. This can cause timeouts and instability.
distributed.core - INFO - Event loop was unresponsive in Worker for 3.39s.  This is often caused by long-running GIL-holding functions or moving large chunks of data. This can cause timeouts and instability.
tornado.application - ERROR - Exception in callback functools.partial(<bound method IOLoop._discard_future_result of <tornado.platform.asyncio.AsyncIOLoop object at 0x2aea0cbd9160>>, <Task finished coro=<Worker.memory_monitor() done, defined at /home/ad/alberta/.conda/envs/perf-pangeo/lib/python3.6/site-packages/distributed/worker.py:2611> exception=OSError(122, 'Disk quota exceeded')>)
Traceback (most recent call last):
  File "/home/ad/alberta/.conda/envs/perf-pangeo/lib/python3.6/site-packages/tornado/ioloop.py", line 743, in _run_callback
    ret = callback()
  File "/home/ad/alberta/.conda/envs/perf-pangeo/lib/python3.6/site-packages/tornado/ioloop.py", line 767, in _discard_future_result
    future.result()
  File "/home/ad/alberta/.conda/envs/perf-pangeo/lib/python3.6/site-packages/distributed/worker.py", line 2681, in memory_monitor
    k, v, weight = self.data.fast.evict()
  File "/home/ad/alberta/.conda/envs/perf-pangeo/lib/python3.6/site-packages/zict/lru.py", line 89, in evict
    cb(k, v)
  File "/home/ad/alberta/.conda/envs/perf-pangeo/lib/python3.6/site-packages/zict/buffer.py", line 60, in fast_to_slow
    self.slow[key] = value
  File "/home/ad/alberta/.conda/envs/perf-pangeo/lib/python3.6/site-packages/zict/func.py", line 41, in __setitem__
    self.d[key] = self.dump(value)
  File "/home/ad/alberta/.conda/envs/perf-pangeo/lib/python3.6/site-packages/zict/file.py", line 84, in __setitem__
    f.write(value)
OSError: [Errno 122] Disk quota exceeded
distributed.core - INFO - Event loop was unresponsive in Worker for 4.34s.  This is often caused by long-running GIL-holding functions or moving large chunks of data. This can cause timeouts and instability.
distributed.worker - ERROR - "('mean_combine-partial-c17c2ae4ec220479d2d373520f89eb8a', 569, 0, 0)"
Traceback (most recent call last):
  File "/home/ad/alberta/.conda/envs/perf-pangeo/lib/python3.6/site-packages/distributed/worker.py", line 2511, in execute
    data[k] = self.data[k]
  File "/home/ad/alberta/.conda/envs/perf-pangeo/lib/python3.6/site-packages/zict/buffer.py", line 80, in __getitem__
    raise KeyError(key)
KeyError: "('mean_combine-partial-c17c2ae4ec220479d2d373520f89eb8a', 569, 0, 0)"

During handling of the above exception, another exception occurred:

Traceback (most recent call last):
  File "/home/ad/alberta/.conda/envs/perf-pangeo/lib/python3.6/site-packages/distributed/worker.py", line 2515, in execute
    data[k] = Actor(type(self.actors[k]), self.address, k, self)
KeyError: "('mean_combine-partial-c17c2ae4ec220479d2d373520f89eb8a', 569, 0, 0)"
tornado.application - ERROR - Exception in callback functools.partial(<bound method IOLoop._discard_future_result of <tornado.platform.asyncio.AsyncIOLoop object at 0x2aea0cbd9160>>, <Task finished coro=<Worker.execute() done, defined at /home/ad/alberta/.conda/envs/perf-pangeo/lib/python3.6/site-packages/distributed/worker.py:2494> exception=KeyError("('mean_combine-partial-c17c2ae4ec220479d2d373520f89eb8a', 569, 0, 0)",)>)
Traceback (most recent call last):
  File "/home/ad/alberta/.conda/envs/perf-pangeo/lib/python3.6/site-packages/distributed/worker.py", line 2511, in execute
    data[k] = self.data[k]
  File "/home/ad/alberta/.conda/envs/perf-pangeo/lib/python3.6/site-packages/zict/buffer.py", line 80, in __getitem__
    raise KeyError(key)
KeyError: "('mean_combine-partial-c17c2ae4ec220479d2d373520f89eb8a', 569, 0, 0)"

During handling of the above exception, another exception occurred:

Traceback (most recent call last):
  File "/home/ad/alberta/.conda/envs/perf-pangeo/lib/python3.6/site-packages/tornado/ioloop.py", line 743, in _run_callback
    ret = callback()
  File "/home/ad/alberta/.conda/envs/perf-pangeo/lib/python3.6/site-packages/tornado/ioloop.py", line 767, in _discard_future_result
    future.result()
  File "/home/ad/alberta/.conda/envs/perf-pangeo/lib/python3.6/site-packages/distributed/worker.py", line 2515, in execute
    data[k] = Actor(type(self.actors[k]), self.address, k, self)
KeyError: "('mean_combine-partial-c17c2ae4ec220479d2d373520f89eb8a', 569, 0, 0)"
distributed.worker - ERROR - Worker stream died during communication: tcp://10.120.40.89:41049
Traceback (most recent call last):
  File "/home/ad/alberta/.conda/envs/perf-pangeo/lib/python3.6/site-packages/distributed/comm/tcp.py", line 184, in read
    n_frames = await stream.read_bytes(8)
tornado.iostream.StreamClosedError: Stream is closed

During handling of the above exception, another exception occurred:

Traceback (most recent call last):
  File "/home/ad/alberta/.conda/envs/perf-pangeo/lib/python3.6/site-packages/distributed/worker.py", line 1980, in gather_dep
    self.rpc, deps, worker, who=self.address
  File "/home/ad/alberta/.conda/envs/perf-pangeo/lib/python3.6/site-packages/distributed/worker.py", line 3251, in get_data_from_worker
    return await retry_operation(_get_data, operation="get_data_from_worker")
  File "/home/ad/alberta/.conda/envs/perf-pangeo/lib/python3.6/site-packages/distributed/utils_comm.py", line 390, in retry_operation
    operation=operation,
  File "/home/ad/alberta/.conda/envs/perf-pangeo/lib/python3.6/site-packages/distributed/utils_comm.py", line 370, in retry
    return await coro()
  File "/home/ad/alberta/.conda/envs/perf-pangeo/lib/python3.6/site-packages/distributed/worker.py", line 3238, in _get_data
    max_connections=max_connections,
  File "/home/ad/alberta/.conda/envs/perf-pangeo/lib/python3.6/site-packages/distributed/core.py", line 589, in send_recv
    response = await comm.read(deserializers=deserializers)
  File "/home/ad/alberta/.conda/envs/perf-pangeo/lib/python3.6/site-packages/distributed/comm/tcp.py", line 199, in read
    convert_stream_closed_error(self, e)
  File "/home/ad/alberta/.conda/envs/perf-pangeo/lib/python3.6/site-packages/distributed/comm/tcp.py", line 123, in convert_stream_closed_error
    raise CommClosedError("in %s: %s" % (obj, exc))
distributed.comm.core.CommClosedError: in <closed TCP>: Stream is closed
distributed.worker - INFO - Can't find dependencies for key ('mean_combine-partial-c17c2ae4ec220479d2d373520f89eb8a', 572, 0, 0)
distributed.worker - INFO - Dependent not found: ('mean_combine-partial-ea26edd6ea215345d2db27703f9d4c15', 2288, 0, 0) 0 .  Asking scheduler
distributed.worker - INFO - Dependent not found: ('mean_combine-partial-ea26edd6ea215345d2db27703f9d4c15', 2289, 0, 0) 0 .  Asking scheduler
distributed.worker - INFO - Dependent not found: ('mean_combine-partial-ea26edd6ea215345d2db27703f9d4c15', 2290, 0, 0) 0 .  Asking scheduler
distributed.worker - INFO - Can't find dependencies for key ('mean_combine-partial-c17c2ae4ec220479d2d373520f89eb8a', 572, 0, 0)
distributed.worker - INFO - Can't find dependencies for key ('mean_combine-partial-ea26edd6ea215345d2db27703f9d4c15', 2312, 0, 0)
distributed.worker - INFO - Dependent not found: ('mean_chunk-5c95da98151b93916264b226a1972684', 9250, 0, 0) 0 .  Asking scheduler
distributed.worker - INFO - Dependent not found: ('mean_chunk-5c95da98151b93916264b226a1972684', 9249, 0, 0) 0 .  Asking scheduler
distributed.worker - INFO - Can't find dependencies for key ('mean_combine-partial-ea26edd6ea215345d2db27703f9d4c15', 2316, 0, 0)
distributed.worker - INFO - Dependent not found: ('mean_chunk-5c95da98151b93916264b226a1972684', 9265, 0, 0) 0 .  Asking scheduler
distributed.worker - INFO - Dependent not found: ('mean_chunk-5c95da98151b93916264b226a1972684', 9266, 0, 0) 0 .  Asking scheduler
distributed.worker - INFO - Dependent not found: ('mean_chunk-5c95da98151b93916264b226a1972684', 9267, 0, 0) 0 .  Asking scheduler
distributed.core - INFO - Event loop was unresponsive in Worker for 3.19s.  This is often caused by long-running GIL-holding functions or moving large chunks of data. This can cause timeouts and instability.
distributed.core - INFO - Event loop was unresponsive in Worker for 3.20s.  This is often caused by long-running GIL-holding functions or moving large chunks of data. This can cause timeouts and instability.
distributed.core - INFO - Event loop was unresponsive in Worker for 3.28s.  This is often caused by long-running GIL-holding functions or moving large chunks of data. This can cause timeouts and instability.
distributed.core - INFO - Event loop was unresponsive in Worker for 4.89s.  This is often caused by long-running GIL-holding functions or moving large chunks of data. This can cause timeouts and instability.
distributed.core - INFO - Event loop was unresponsive in Worker for 3.11s.  This is often caused by long-running GIL-holding functions or moving large chunks of data. This can cause timeouts and instability.
distributed.core - INFO - Event loop was unresponsive in Worker for 7.14s.  This is often caused by long-running GIL-holding functions or moving large chunks of data. This can cause timeouts and instability.
distributed.core - INFO - Event loop was unresponsive in Worker for 4.20s.  This is often caused by long-running GIL-holding functions or moving large chunks of data. This can cause timeouts and instability.
distributed.core - INFO - Event loop was unresponsive in Worker for 3.00s.  This is often caused by long-running GIL-holding functions or moving large chunks of data. This can cause timeouts and instability.
distributed.worker - INFO - Failed to put key in memory
Traceback (most recent call last):
  File "/home/ad/alberta/.conda/envs/perf-pangeo/lib/python3.6/site-packages/distributed/worker.py", line 1698, in transition_executing_done
    self.put_key_in_memory(key, value, transition=False)
  File "/home/ad/alberta/.conda/envs/perf-pangeo/lib/python3.6/site-packages/distributed/worker.py", line 1921, in put_key_in_memory
    self.data[key] = value
  File "/home/ad/alberta/.conda/envs/perf-pangeo/lib/python3.6/site-packages/zict/buffer.py", line 87, in __setitem__
    self.fast[key] = value
  File "/home/ad/alberta/.conda/envs/perf-pangeo/lib/python3.6/site-packages/zict/lru.py", line 70, in __setitem__
    self.evict()
  File "/home/ad/alberta/.conda/envs/perf-pangeo/lib/python3.6/site-packages/zict/lru.py", line 89, in evict
    cb(k, v)
  File "/home/ad/alberta/.conda/envs/perf-pangeo/lib/python3.6/site-packages/zict/buffer.py", line 60, in fast_to_slow
    self.slow[key] = value
  File "/home/ad/alberta/.conda/envs/perf-pangeo/lib/python3.6/site-packages/zict/func.py", line 41, in __setitem__
    self.d[key] = self.dump(value)
  File "/home/ad/alberta/.conda/envs/perf-pangeo/lib/python3.6/site-packages/zict/file.py", line 84, in __setitem__
    f.write(value)
OSError: [Errno 122] Disk quota exceeded
distributed.core - INFO - Event loop was unresponsive in Worker for 3.74s.  This is often caused by long-running GIL-holding functions or moving large chunks of data. This can cause timeouts and instability.
distributed.nanny - WARNING - Worker exceeded 95% memory budget. Restarting
distributed.nanny - INFO - Worker process 14128 was killed by signal 15
/home/ad/alberta/.conda/envs/perf-pangeo/lib/python3.6/multiprocessing/semaphore_tracker.py:143: UserWarning: semaphore_tracker: There appear to be 1 leaked semaphores to clean up at shutdown
  len(cache))
distributed.nanny - WARNING - Restarting worker
distributed.worker - INFO -       Start worker at:   tcp://10.120.40.89:34517
distributed.worker - INFO -          Listening to:   tcp://10.120.40.89:34517
distributed.worker - INFO -          dashboard at:         10.120.40.89:40907
distributed.worker - INFO - Waiting to connect to:   tcp://10.120.43.21:37853
distributed.worker - INFO - -------------------------------------------------
distributed.worker - INFO -               Threads:                          1
distributed.worker - INFO -                Memory:                    8.00 GB
distributed.worker - INFO -       Local Directory: /home/ad/alberta/dask-worker-space/worker-s9iyfjry
distributed.worker - INFO - -------------------------------------------------
distributed.worker - INFO -         Registered to:   tcp://10.120.43.21:37853
distributed.worker - INFO - -------------------------------------------------
distributed.core - INFO - Starting established connection
distributed.core - INFO - Event loop was unresponsive in Worker for 9.11s.  This is often caused by long-running GIL-holding functions or moving large chunks of data. This can cause timeouts and instability.
distributed.core - INFO - Event loop was unresponsive in Worker for 6.76s.  This is often caused by long-running GIL-holding functions or moving large chunks of data. This can cause timeouts and instability.
distributed.core - INFO - Event loop was unresponsive in Worker for 8.45s.  This is often caused by long-running GIL-holding functions or moving large chunks of data. This can cause timeouts and instability.
tornado.application - ERROR - Exception in callback functools.partial(<bound method IOLoop._discard_future_result of <tornado.platform.asyncio.AsyncIOLoop object at 0x2b853644d198>>, <Task finished coro=<Worker.memory_monitor() done, defined at /home/ad/alberta/.conda/envs/perf-pangeo/lib/python3.6/site-packages/distributed/worker.py:2611> exception=OSError(122, 'Disk quota exceeded')>)
Traceback (most recent call last):
  File "/home/ad/alberta/.conda/envs/perf-pangeo/lib/python3.6/site-packages/tornado/ioloop.py", line 743, in _run_callback
    ret = callback()
  File "/home/ad/alberta/.conda/envs/perf-pangeo/lib/python3.6/site-packages/tornado/ioloop.py", line 767, in _discard_future_result
    future.result()
  File "/home/ad/alberta/.conda/envs/perf-pangeo/lib/python3.6/site-packages/distributed/worker.py", line 2681, in memory_monitor
    k, v, weight = self.data.fast.evict()
  File "/home/ad/alberta/.conda/envs/perf-pangeo/lib/python3.6/site-packages/zict/lru.py", line 89, in evict
    cb(k, v)
  File "/home/ad/alberta/.conda/envs/perf-pangeo/lib/python3.6/site-packages/zict/buffer.py", line 60, in fast_to_slow
    self.slow[key] = value
  File "/home/ad/alberta/.conda/envs/perf-pangeo/lib/python3.6/site-packages/zict/func.py", line 41, in __setitem__
    self.d[key] = self.dump(value)
  File "/home/ad/alberta/.conda/envs/perf-pangeo/lib/python3.6/site-packages/zict/file.py", line 84, in __setitem__
    f.write(value)
OSError: [Errno 122] Disk quota exceeded
distributed.worker - ERROR - failed during get data with tcp://10.120.40.89:34517 -> tcp://10.120.40.89:34970
Traceback (most recent call last):
  File "/home/ad/alberta/.conda/envs/perf-pangeo/lib/python3.6/site-packages/distributed/comm/tcp.py", line 246, in write
    await future
tornado.iostream.StreamClosedError: Stream is closed

During handling of the above exception, another exception occurred:

Traceback (most recent call last):
  File "/home/ad/alberta/.conda/envs/perf-pangeo/lib/python3.6/site-packages/distributed/worker.py", line 1275, in get_data
    compressed = await comm.write(msg, serializers=serializers)
  File "/home/ad/alberta/.conda/envs/perf-pangeo/lib/python3.6/site-packages/distributed/comm/tcp.py", line 250, in write
    convert_stream_closed_error(self, e)
  File "/home/ad/alberta/.conda/envs/perf-pangeo/lib/python3.6/site-packages/distributed/comm/tcp.py", line 121, in convert_stream_closed_error
    raise CommClosedError("in %s: %s: %s" % (obj, exc.__class__.__name__, exc))
distributed.comm.core.CommClosedError: in <closed TCP>: ConnectionResetError: [Errno 104] Connection reset by peer
distributed.worker - ERROR - Worker stream died during communication: tcp://10.120.40.89:34970
Traceback (most recent call last):
  File "/home/ad/alberta/.conda/envs/perf-pangeo/lib/python3.6/site-packages/distributed/comm/tcp.py", line 193, in read
    n = await stream.read_into(frame)
tornado.iostream.StreamClosedError: Stream is closed

During handling of the above exception, another exception occurred:

Traceback (most recent call last):
  File "/home/ad/alberta/.conda/envs/perf-pangeo/lib/python3.6/site-packages/distributed/worker.py", line 1980, in gather_dep
    self.rpc, deps, worker, who=self.address
  File "/home/ad/alberta/.conda/envs/perf-pangeo/lib/python3.6/site-packages/distributed/worker.py", line 3251, in get_data_from_worker
    return await retry_operation(_get_data, operation="get_data_from_worker")
  File "/home/ad/alberta/.conda/envs/perf-pangeo/lib/python3.6/site-packages/distributed/utils_comm.py", line 390, in retry_operation
    operation=operation,
  File "/home/ad/alberta/.conda/envs/perf-pangeo/lib/python3.6/site-packages/distributed/utils_comm.py", line 370, in retry
    return await coro()
  File "/home/ad/alberta/.conda/envs/perf-pangeo/lib/python3.6/site-packages/distributed/worker.py", line 3238, in _get_data
    max_connections=max_connections,
  File "/home/ad/alberta/.conda/envs/perf-pangeo/lib/python3.6/site-packages/distributed/core.py", line 589, in send_recv
    response = await comm.read(deserializers=deserializers)
  File "/home/ad/alberta/.conda/envs/perf-pangeo/lib/python3.6/site-packages/distributed/comm/tcp.py", line 199, in read
    convert_stream_closed_error(self, e)
  File "/home/ad/alberta/.conda/envs/perf-pangeo/lib/python3.6/site-packages/distributed/comm/tcp.py", line 123, in convert_stream_closed_error
    raise CommClosedError("in %s: %s" % (obj, exc))
distributed.comm.core.CommClosedError: in <closed TCP>: Stream is closed
distributed.worker - INFO - Can't find dependencies for key ('mean_combine-partial-ea26edd6ea215345d2db27703f9d4c15', 2894, 0, 0)
distributed.core - INFO - Lost connection to 'tcp://10.120.40.89:55008': in <closed TCP>: ConnectionResetError: [Errno 104] Connection reset by peer
distributed.worker - INFO - Dependent not found: ('mean_chunk-5c95da98151b93916264b226a1972684', 11577, 0, 0) 0 .  Asking scheduler
distributed.core - INFO - Event loop was unresponsive in Worker for 6.54s.  This is often caused by long-running GIL-holding functions or moving large chunks of data. This can cause timeouts and instability.
distributed.core - INFO - Event loop was unresponsive in Worker for 5.65s.  This is often caused by long-running GIL-holding functions or moving large chunks of data. This can cause timeouts and instability.
distributed.worker - ERROR - "('mean_combine-partial-ea26edd6ea215345d2db27703f9d4c15', 2893, 0, 0)"
Traceback (most recent call last):
  File "/home/ad/alberta/.conda/envs/perf-pangeo/lib/python3.6/site-packages/distributed/worker.py", line 2511, in execute
    data[k] = self.data[k]
  File "/home/ad/alberta/.conda/envs/perf-pangeo/lib/python3.6/site-packages/zict/buffer.py", line 80, in __getitem__
    raise KeyError(key)
KeyError: "('mean_combine-partial-ea26edd6ea215345d2db27703f9d4c15', 2893, 0, 0)"

During handling of the above exception, another exception occurred:

Traceback (most recent call last):
  File "/home/ad/alberta/.conda/envs/perf-pangeo/lib/python3.6/site-packages/distributed/worker.py", line 2515, in execute
    data[k] = Actor(type(self.actors[k]), self.address, k, self)
KeyError: "('mean_combine-partial-ea26edd6ea215345d2db27703f9d4c15', 2893, 0, 0)"
tornado.application - ERROR - Exception in callback functools.partial(<bound method IOLoop._discard_future_result of <tornado.platform.asyncio.AsyncIOLoop object at 0x2b853644d198>>, <Task finished coro=<Worker.execute() done, defined at /home/ad/alberta/.conda/envs/perf-pangeo/lib/python3.6/site-packages/distributed/worker.py:2494> exception=KeyError("('mean_combine-partial-ea26edd6ea215345d2db27703f9d4c15', 2893, 0, 0)",)>)
Traceback (most recent call last):
  File "/home/ad/alberta/.conda/envs/perf-pangeo/lib/python3.6/site-packages/distributed/worker.py", line 2511, in execute
    data[k] = self.data[k]
  File "/home/ad/alberta/.conda/envs/perf-pangeo/lib/python3.6/site-packages/zict/buffer.py", line 80, in __getitem__
    raise KeyError(key)
KeyError: "('mean_combine-partial-ea26edd6ea215345d2db27703f9d4c15', 2893, 0, 0)"

During handling of the above exception, another exception occurred:

Traceback (most recent call last):
  File "/home/ad/alberta/.conda/envs/perf-pangeo/lib/python3.6/site-packages/tornado/ioloop.py", line 743, in _run_callback
    ret = callback()
  File "/home/ad/alberta/.conda/envs/perf-pangeo/lib/python3.6/site-packages/tornado/ioloop.py", line 767, in _discard_future_result
    future.result()
  File "/home/ad/alberta/.conda/envs/perf-pangeo/lib/python3.6/site-packages/distributed/worker.py", line 2515, in execute
    data[k] = Actor(type(self.actors[k]), self.address, k, self)
KeyError: "('mean_combine-partial-ea26edd6ea215345d2db27703f9d4c15', 2893, 0, 0)"
distributed.core - INFO - Event loop was unresponsive in Worker for 4.49s.  This is often caused by long-running GIL-holding functions or moving large chunks of data. This can cause timeouts and instability.
distributed.core - INFO - Event loop was unresponsive in Worker for 5.77s.  This is often caused by long-running GIL-holding functions or moving large chunks of data. This can cause timeouts and instability.
distributed.core - INFO - Event loop was unresponsive in Worker for 4.72s.  This is often caused by long-running GIL-holding functions or moving large chunks of data. This can cause timeouts and instability.
distributed.core - INFO - Event loop was unresponsive in Worker for 5.54s.  This is often caused by long-running GIL-holding functions or moving large chunks of data. This can cause timeouts and instability.
distributed.core - INFO - Event loop was unresponsive in Worker for 5.33s.  This is often caused by long-running GIL-holding functions or moving large chunks of data. This can cause timeouts and instability.
distributed.worker - INFO - Failed to put key in memory
Traceback (most recent call last):
  File "/home/ad/alberta/.conda/envs/perf-pangeo/lib/python3.6/site-packages/distributed/worker.py", line 1698, in transition_executing_done
    self.put_key_in_memory(key, value, transition=False)
  File "/home/ad/alberta/.conda/envs/perf-pangeo/lib/python3.6/site-packages/distributed/worker.py", line 1921, in put_key_in_memory
    self.data[key] = value
  File "/home/ad/alberta/.conda/envs/perf-pangeo/lib/python3.6/site-packages/zict/buffer.py", line 87, in __setitem__
    self.fast[key] = value
  File "/home/ad/alberta/.conda/envs/perf-pangeo/lib/python3.6/site-packages/zict/lru.py", line 70, in __setitem__
    self.evict()
  File "/home/ad/alberta/.conda/envs/perf-pangeo/lib/python3.6/site-packages/zict/lru.py", line 89, in evict
    cb(k, v)
  File "/home/ad/alberta/.conda/envs/perf-pangeo/lib/python3.6/site-packages/zict/buffer.py", line 60, in fast_to_slow
    self.slow[key] = value
  File "/home/ad/alberta/.conda/envs/perf-pangeo/lib/python3.6/site-packages/zict/func.py", line 41, in __setitem__
    self.d[key] = self.dump(value)
  File "/home/ad/alberta/.conda/envs/perf-pangeo/lib/python3.6/site-packages/zict/file.py", line 84, in __setitem__
    f.write(value)
OSError: [Errno 122] Disk quota exceeded
distributed.core - INFO - Event loop was unresponsive in Worker for 5.29s.  This is often caused by long-running GIL-holding functions or moving large chunks of data. This can cause timeouts and instability.
distributed.worker - ERROR - "('mean_combine-partial-c17c2ae4ec220479d2d373520f89eb8a', 724, 0, 0)"
Traceback (most recent call last):
  File "/home/ad/alberta/.conda/envs/perf-pangeo/lib/python3.6/site-packages/distributed/worker.py", line 2511, in execute
    data[k] = self.data[k]
  File "/home/ad/alberta/.conda/envs/perf-pangeo/lib/python3.6/site-packages/zict/buffer.py", line 80, in __getitem__
    raise KeyError(key)
KeyError: "('mean_combine-partial-c17c2ae4ec220479d2d373520f89eb8a', 724, 0, 0)"

During handling of the above exception, another exception occurred:

Traceback (most recent call last):
  File "/home/ad/alberta/.conda/envs/perf-pangeo/lib/python3.6/site-packages/distributed/worker.py", line 2515, in execute
    data[k] = Actor(type(self.actors[k]), self.address, k, self)
KeyError: "('mean_combine-partial-c17c2ae4ec220479d2d373520f89eb8a', 724, 0, 0)"
tornado.application - ERROR - Exception in callback functools.partial(<bound method IOLoop._discard_future_result of <tornado.platform.asyncio.AsyncIOLoop object at 0x2b853644d198>>, <Task finished coro=<Worker.execute() done, defined at /home/ad/alberta/.conda/envs/perf-pangeo/lib/python3.6/site-packages/distributed/worker.py:2494> exception=KeyError("('mean_combine-partial-c17c2ae4ec220479d2d373520f89eb8a', 724, 0, 0)",)>)
Traceback (most recent call last):
  File "/home/ad/alberta/.conda/envs/perf-pangeo/lib/python3.6/site-packages/distributed/worker.py", line 2511, in execute
    data[k] = self.data[k]
  File "/home/ad/alberta/.conda/envs/perf-pangeo/lib/python3.6/site-packages/zict/buffer.py", line 80, in __getitem__
    raise KeyError(key)
KeyError: "('mean_combine-partial-c17c2ae4ec220479d2d373520f89eb8a', 724, 0, 0)"

During handling of the above exception, another exception occurred:

Traceback (most recent call last):
  File "/home/ad/alberta/.conda/envs/perf-pangeo/lib/python3.6/site-packages/tornado/ioloop.py", line 743, in _run_callback
    ret = callback()
  File "/home/ad/alberta/.conda/envs/perf-pangeo/lib/python3.6/site-packages/tornado/ioloop.py", line 767, in _discard_future_result
    future.result()
  File "/home/ad/alberta/.conda/envs/perf-pangeo/lib/python3.6/site-packages/distributed/worker.py", line 2515, in execute
    data[k] = Actor(type(self.actors[k]), self.address, k, self)
KeyError: "('mean_combine-partial-c17c2ae4ec220479d2d373520f89eb8a', 724, 0, 0)"
distributed.worker - INFO - Can't find dependencies for key ('mean_combine-partial-ea26edd6ea215345d2db27703f9d4c15', 2921, 0, 0)
distributed.worker - INFO - Dependent not found: ('mean_chunk-5c95da98151b93916264b226a1972684', 11684, 0, 0) 0 .  Asking scheduler
distributed.worker - INFO - Can't find dependencies for key ('mean_combine-partial-ea26edd6ea215345d2db27703f9d4c15', 2921, 0, 0)
distributed.core - INFO - Event loop was unresponsive in Worker for 3.14s.  This is often caused by long-running GIL-holding functions or moving large chunks of data. This can cause timeouts and instability.
distributed.nanny - WARNING - Worker exceeded 95% memory budget. Restarting
distributed.nanny - INFO - Worker process 24393 was killed by signal 15
/home/ad/alberta/.conda/envs/perf-pangeo/lib/python3.6/multiprocessing/semaphore_tracker.py:143: UserWarning: semaphore_tracker: There appear to be 1 leaked semaphores to clean up at shutdown
  len(cache))
distributed.nanny - WARNING - Restarting worker
distributed.dask_worker - INFO - Exiting on signal 15
distributed.nanny - INFO - Closing Nanny at 'tcp://10.120.40.89:38905'
distributed.nanny - INFO - Worker process 20815 was killed by signal 15
distributed.dask_worker - INFO - End worker
