distributed.nanny - INFO -         Start Nanny at: 'tcp://10.120.40.89:35807'
distributed.worker - INFO -       Start worker at:   tcp://10.120.40.89:37536
distributed.worker - INFO -          Listening to:   tcp://10.120.40.89:37536
distributed.worker - INFO -          dashboard at:         10.120.40.89:39730
distributed.worker - INFO - Waiting to connect to:   tcp://10.120.43.21:43577
distributed.worker - INFO - -------------------------------------------------
distributed.worker - INFO -               Threads:                          1
distributed.worker - INFO -                Memory:                    8.00 GB
distributed.worker - INFO -       Local Directory: /home/ad/alberta/dask-worker-space/worker-c85y90rm
distributed.worker - INFO - -------------------------------------------------
distributed.worker - INFO -         Registered to:   tcp://10.120.43.21:43577
distributed.worker - INFO - -------------------------------------------------
distributed.core - INFO - Starting established connection
distributed.core - INFO - Event loop was unresponsive in Worker for 6.10s.  This is often caused by long-running GIL-holding functions or moving large chunks of data. This can cause timeouts and instability.
distributed.core - INFO - Event loop was unresponsive in Worker for 6.01s.  This is often caused by long-running GIL-holding functions or moving large chunks of data. This can cause timeouts and instability.
distributed.core - INFO - Event loop was unresponsive in Worker for 8.36s.  This is often caused by long-running GIL-holding functions or moving large chunks of data. This can cause timeouts and instability.
distributed.core - INFO - Event loop was unresponsive in Worker for 6.25s.  This is often caused by long-running GIL-holding functions or moving large chunks of data. This can cause timeouts and instability.
distributed.core - INFO - Event loop was unresponsive in Worker for 7.45s.  This is often caused by long-running GIL-holding functions or moving large chunks of data. This can cause timeouts and instability.
distributed.core - INFO - Event loop was unresponsive in Worker for 5.93s.  This is often caused by long-running GIL-holding functions or moving large chunks of data. This can cause timeouts and instability.
distributed.core - INFO - Event loop was unresponsive in Worker for 4.62s.  This is often caused by long-running GIL-holding functions or moving large chunks of data. This can cause timeouts and instability.
distributed.core - INFO - Event loop was unresponsive in Worker for 3.35s.  This is often caused by long-running GIL-holding functions or moving large chunks of data. This can cause timeouts and instability.
distributed.core - INFO - Event loop was unresponsive in Worker for 6.04s.  This is often caused by long-running GIL-holding functions or moving large chunks of data. This can cause timeouts and instability.
distributed.utils_perf - INFO - full garbage collection released 35.48 MB from 780 reference cycles (threshold: 10.00 MB)
distributed.core - INFO - Event loop was unresponsive in Worker for 8.56s.  This is often caused by long-running GIL-holding functions or moving large chunks of data. This can cause timeouts and instability.
tornado.application - ERROR - Exception in callback functools.partial(<bound method IOLoop._discard_future_result of <tornado.platform.asyncio.AsyncIOLoop object at 0x2b276741e160>>, <Task finished coro=<Worker.memory_monitor() done, defined at /home/ad/alberta/.conda/envs/perf-pangeo/lib/python3.6/site-packages/distributed/worker.py:2611> exception=OSError(122, 'Disk quota exceeded')>)
Traceback (most recent call last):
  File "/home/ad/alberta/.conda/envs/perf-pangeo/lib/python3.6/site-packages/tornado/ioloop.py", line 743, in _run_callback
    ret = callback()
  File "/home/ad/alberta/.conda/envs/perf-pangeo/lib/python3.6/site-packages/tornado/ioloop.py", line 767, in _discard_future_result
    future.result()
  File "/home/ad/alberta/.conda/envs/perf-pangeo/lib/python3.6/site-packages/distributed/worker.py", line 2681, in memory_monitor
    k, v, weight = self.data.fast.evict()
  File "/home/ad/alberta/.conda/envs/perf-pangeo/lib/python3.6/site-packages/zict/lru.py", line 89, in evict
    cb(k, v)
  File "/home/ad/alberta/.conda/envs/perf-pangeo/lib/python3.6/site-packages/zict/buffer.py", line 60, in fast_to_slow
    self.slow[key] = value
  File "/home/ad/alberta/.conda/envs/perf-pangeo/lib/python3.6/site-packages/zict/func.py", line 41, in __setitem__
    self.d[key] = self.dump(value)
  File "/home/ad/alberta/.conda/envs/perf-pangeo/lib/python3.6/site-packages/zict/file.py", line 84, in __setitem__
    f.write(value)
OSError: [Errno 122] Disk quota exceeded
distributed.core - INFO - Event loop was unresponsive in Worker for 5.84s.  This is often caused by long-running GIL-holding functions or moving large chunks of data. This can cause timeouts and instability.
distributed.worker - ERROR - "('mean_combine-partial-6b33a88a4c41df7713d84d90af2bf735', 176, 0, 0)"
Traceback (most recent call last):
  File "/home/ad/alberta/.conda/envs/perf-pangeo/lib/python3.6/site-packages/distributed/worker.py", line 2511, in execute
    data[k] = self.data[k]
  File "/home/ad/alberta/.conda/envs/perf-pangeo/lib/python3.6/site-packages/zict/buffer.py", line 80, in __getitem__
    raise KeyError(key)
KeyError: "('mean_combine-partial-6b33a88a4c41df7713d84d90af2bf735', 176, 0, 0)"

During handling of the above exception, another exception occurred:

Traceback (most recent call last):
  File "/home/ad/alberta/.conda/envs/perf-pangeo/lib/python3.6/site-packages/distributed/worker.py", line 2515, in execute
    data[k] = Actor(type(self.actors[k]), self.address, k, self)
KeyError: "('mean_combine-partial-6b33a88a4c41df7713d84d90af2bf735', 176, 0, 0)"
tornado.application - ERROR - Exception in callback functools.partial(<bound method IOLoop._discard_future_result of <tornado.platform.asyncio.AsyncIOLoop object at 0x2b276741e160>>, <Task finished coro=<Worker.execute() done, defined at /home/ad/alberta/.conda/envs/perf-pangeo/lib/python3.6/site-packages/distributed/worker.py:2494> exception=KeyError("('mean_combine-partial-6b33a88a4c41df7713d84d90af2bf735', 176, 0, 0)",)>)
Traceback (most recent call last):
  File "/home/ad/alberta/.conda/envs/perf-pangeo/lib/python3.6/site-packages/distributed/worker.py", line 2511, in execute
    data[k] = self.data[k]
  File "/home/ad/alberta/.conda/envs/perf-pangeo/lib/python3.6/site-packages/zict/buffer.py", line 80, in __getitem__
    raise KeyError(key)
KeyError: "('mean_combine-partial-6b33a88a4c41df7713d84d90af2bf735', 176, 0, 0)"

During handling of the above exception, another exception occurred:

Traceback (most recent call last):
  File "/home/ad/alberta/.conda/envs/perf-pangeo/lib/python3.6/site-packages/tornado/ioloop.py", line 743, in _run_callback
    ret = callback()
  File "/home/ad/alberta/.conda/envs/perf-pangeo/lib/python3.6/site-packages/tornado/ioloop.py", line 767, in _discard_future_result
    future.result()
  File "/home/ad/alberta/.conda/envs/perf-pangeo/lib/python3.6/site-packages/distributed/worker.py", line 2515, in execute
    data[k] = Actor(type(self.actors[k]), self.address, k, self)
KeyError: "('mean_combine-partial-6b33a88a4c41df7713d84d90af2bf735', 176, 0, 0)"
distributed.core - INFO - Event loop was unresponsive in Worker for 3.00s.  This is often caused by long-running GIL-holding functions or moving large chunks of data. This can cause timeouts and instability.
distributed.worker - INFO - Can't find dependencies for key ('mean_combine-partial-09e948da8f943fba973e918b66c5f1e7', 46, 0, 0)
distributed.worker - INFO - Dependent not found: ('mean_combine-partial-6b33a88a4c41df7713d84d90af2bf735', 185, 0, 0) 0 .  Asking scheduler
distributed.core - INFO - Event loop was unresponsive in Worker for 5.39s.  This is often caused by long-running GIL-holding functions or moving large chunks of data. This can cause timeouts and instability.
distributed.worker - INFO - Failed to put key in memory
Traceback (most recent call last):
  File "/home/ad/alberta/.conda/envs/perf-pangeo/lib/python3.6/site-packages/distributed/worker.py", line 1698, in transition_executing_done
    self.put_key_in_memory(key, value, transition=False)
  File "/home/ad/alberta/.conda/envs/perf-pangeo/lib/python3.6/site-packages/distributed/worker.py", line 1921, in put_key_in_memory
    self.data[key] = value
  File "/home/ad/alberta/.conda/envs/perf-pangeo/lib/python3.6/site-packages/zict/buffer.py", line 87, in __setitem__
    self.fast[key] = value
  File "/home/ad/alberta/.conda/envs/perf-pangeo/lib/python3.6/site-packages/zict/lru.py", line 70, in __setitem__
    self.evict()
  File "/home/ad/alberta/.conda/envs/perf-pangeo/lib/python3.6/site-packages/zict/lru.py", line 89, in evict
    cb(k, v)
  File "/home/ad/alberta/.conda/envs/perf-pangeo/lib/python3.6/site-packages/zict/buffer.py", line 60, in fast_to_slow
    self.slow[key] = value
  File "/home/ad/alberta/.conda/envs/perf-pangeo/lib/python3.6/site-packages/zict/func.py", line 41, in __setitem__
    self.d[key] = self.dump(value)
  File "/home/ad/alberta/.conda/envs/perf-pangeo/lib/python3.6/site-packages/zict/file.py", line 84, in __setitem__
    f.write(value)
OSError: [Errno 122] Disk quota exceeded
distributed.core - INFO - Event loop was unresponsive in Worker for 3.20s.  This is often caused by long-running GIL-holding functions or moving large chunks of data. This can cause timeouts and instability.
distributed.worker - INFO - Failed to put key in memory
Traceback (most recent call last):
  File "/home/ad/alberta/.conda/envs/perf-pangeo/lib/python3.6/site-packages/distributed/worker.py", line 1698, in transition_executing_done
    self.put_key_in_memory(key, value, transition=False)
  File "/home/ad/alberta/.conda/envs/perf-pangeo/lib/python3.6/site-packages/distributed/worker.py", line 1921, in put_key_in_memory
    self.data[key] = value
  File "/home/ad/alberta/.conda/envs/perf-pangeo/lib/python3.6/site-packages/zict/buffer.py", line 87, in __setitem__
    self.fast[key] = value
  File "/home/ad/alberta/.conda/envs/perf-pangeo/lib/python3.6/site-packages/zict/lru.py", line 70, in __setitem__
    self.evict()
  File "/home/ad/alberta/.conda/envs/perf-pangeo/lib/python3.6/site-packages/zict/lru.py", line 89, in evict
    cb(k, v)
  File "/home/ad/alberta/.conda/envs/perf-pangeo/lib/python3.6/site-packages/zict/buffer.py", line 60, in fast_to_slow
    self.slow[key] = value
  File "/home/ad/alberta/.conda/envs/perf-pangeo/lib/python3.6/site-packages/zict/func.py", line 41, in __setitem__
    self.d[key] = self.dump(value)
  File "/home/ad/alberta/.conda/envs/perf-pangeo/lib/python3.6/site-packages/zict/file.py", line 84, in __setitem__
    f.write(value)
OSError: [Errno 122] Disk quota exceeded
distributed.core - INFO - Event loop was unresponsive in Worker for 5.08s.  This is often caused by long-running GIL-holding functions or moving large chunks of data. This can cause timeouts and instability.
distributed.worker - INFO - Failed to put key in memory
Traceback (most recent call last):
  File "/home/ad/alberta/.conda/envs/perf-pangeo/lib/python3.6/site-packages/distributed/worker.py", line 1698, in transition_executing_done
    self.put_key_in_memory(key, value, transition=False)
  File "/home/ad/alberta/.conda/envs/perf-pangeo/lib/python3.6/site-packages/distributed/worker.py", line 1921, in put_key_in_memory
    self.data[key] = value
  File "/home/ad/alberta/.conda/envs/perf-pangeo/lib/python3.6/site-packages/zict/buffer.py", line 87, in __setitem__
    self.fast[key] = value
  File "/home/ad/alberta/.conda/envs/perf-pangeo/lib/python3.6/site-packages/zict/lru.py", line 70, in __setitem__
    self.evict()
  File "/home/ad/alberta/.conda/envs/perf-pangeo/lib/python3.6/site-packages/zict/lru.py", line 89, in evict
    cb(k, v)
  File "/home/ad/alberta/.conda/envs/perf-pangeo/lib/python3.6/site-packages/zict/buffer.py", line 60, in fast_to_slow
    self.slow[key] = value
  File "/home/ad/alberta/.conda/envs/perf-pangeo/lib/python3.6/site-packages/zict/func.py", line 41, in __setitem__
    self.d[key] = self.dump(value)
  File "/home/ad/alberta/.conda/envs/perf-pangeo/lib/python3.6/site-packages/zict/file.py", line 84, in __setitem__
    f.write(value)
OSError: [Errno 122] Disk quota exceeded
distributed.core - INFO - Event loop was unresponsive in Worker for 3.78s.  This is often caused by long-running GIL-holding functions or moving large chunks of data. This can cause timeouts and instability.
distributed.worker - ERROR - "('mean_chunk-2f7384593acde7879d1689441c7ac2ef', 3104, 0, 0)"
Traceback (most recent call last):
  File "/home/ad/alberta/.conda/envs/perf-pangeo/lib/python3.6/site-packages/distributed/worker.py", line 2511, in execute
    data[k] = self.data[k]
  File "/home/ad/alberta/.conda/envs/perf-pangeo/lib/python3.6/site-packages/zict/buffer.py", line 80, in __getitem__
    raise KeyError(key)
KeyError: "('mean_chunk-2f7384593acde7879d1689441c7ac2ef', 3104, 0, 0)"

During handling of the above exception, another exception occurred:

Traceback (most recent call last):
  File "/home/ad/alberta/.conda/envs/perf-pangeo/lib/python3.6/site-packages/distributed/worker.py", line 2515, in execute
    data[k] = Actor(type(self.actors[k]), self.address, k, self)
KeyError: "('mean_chunk-2f7384593acde7879d1689441c7ac2ef', 3104, 0, 0)"
tornado.application - ERROR - Exception in callback functools.partial(<bound method IOLoop._discard_future_result of <tornado.platform.asyncio.AsyncIOLoop object at 0x2b276741e160>>, <Task finished coro=<Worker.execute() done, defined at /home/ad/alberta/.conda/envs/perf-pangeo/lib/python3.6/site-packages/distributed/worker.py:2494> exception=KeyError("('mean_chunk-2f7384593acde7879d1689441c7ac2ef', 3104, 0, 0)",)>)
Traceback (most recent call last):
  File "/home/ad/alberta/.conda/envs/perf-pangeo/lib/python3.6/site-packages/distributed/worker.py", line 2511, in execute
    data[k] = self.data[k]
  File "/home/ad/alberta/.conda/envs/perf-pangeo/lib/python3.6/site-packages/zict/buffer.py", line 80, in __getitem__
    raise KeyError(key)
KeyError: "('mean_chunk-2f7384593acde7879d1689441c7ac2ef', 3104, 0, 0)"

During handling of the above exception, another exception occurred:

Traceback (most recent call last):
  File "/home/ad/alberta/.conda/envs/perf-pangeo/lib/python3.6/site-packages/tornado/ioloop.py", line 743, in _run_callback
    ret = callback()
  File "/home/ad/alberta/.conda/envs/perf-pangeo/lib/python3.6/site-packages/tornado/ioloop.py", line 767, in _discard_future_result
    future.result()
  File "/home/ad/alberta/.conda/envs/perf-pangeo/lib/python3.6/site-packages/distributed/worker.py", line 2515, in execute
    data[k] = Actor(type(self.actors[k]), self.address, k, self)
KeyError: "('mean_chunk-2f7384593acde7879d1689441c7ac2ef', 3104, 0, 0)"
distributed.nanny - WARNING - Worker exceeded 95% memory budget. Restarting
distributed.nanny - INFO - Worker process 18617 was killed by signal 15
/home/ad/alberta/.conda/envs/perf-pangeo/lib/python3.6/multiprocessing/semaphore_tracker.py:143: UserWarning: semaphore_tracker: There appear to be 1 leaked semaphores to clean up at shutdown
  len(cache))
distributed.nanny - WARNING - Restarting worker
/home/ad/alberta/.conda/envs/perf-pangeo/lib/python3.6/contextlib.py:88: UserWarning: Creating scratch directories is taking a surprisingly long time. This is often due to running workers on a network file system. Consider specifying a local-directory to point workers to write scratch data to a local disk.
  next(self.gen)
distributed.worker - INFO -       Start worker at:   tcp://10.120.40.89:45826
distributed.worker - INFO -          Listening to:   tcp://10.120.40.89:45826
distributed.worker - INFO -          dashboard at:         10.120.40.89:45642
distributed.worker - INFO - Waiting to connect to:   tcp://10.120.43.21:43577
distributed.worker - INFO - -------------------------------------------------
distributed.worker - INFO -               Threads:                          1
distributed.worker - INFO -                Memory:                    8.00 GB
distributed.worker - INFO -       Local Directory: /home/ad/alberta/dask-worker-space/worker-gt4nskje
distributed.worker - INFO - -------------------------------------------------
distributed.worker - INFO -         Registered to:   tcp://10.120.43.21:43577
distributed.worker - INFO - -------------------------------------------------
distributed.core - INFO - Starting established connection
distributed.utils_perf - INFO - full garbage collection released 26.30 MB from 6 reference cycles (threshold: 10.00 MB)
distributed.core - INFO - Event loop was unresponsive in Worker for 3.06s.  This is often caused by long-running GIL-holding functions or moving large chunks of data. This can cause timeouts and instability.
distributed.core - INFO - Event loop was unresponsive in Worker for 3.55s.  This is often caused by long-running GIL-holding functions or moving large chunks of data. This can cause timeouts and instability.
distributed.core - INFO - Event loop was unresponsive in Worker for 5.88s.  This is often caused by long-running GIL-holding functions or moving large chunks of data. This can cause timeouts and instability.
distributed.utils_perf - INFO - full garbage collection released 315.99 MB from 674 reference cycles (threshold: 10.00 MB)
distributed.core - INFO - Event loop was unresponsive in Worker for 4.36s.  This is often caused by long-running GIL-holding functions or moving large chunks of data. This can cause timeouts and instability.
distributed.core - INFO - Event loop was unresponsive in Worker for 9.38s.  This is often caused by long-running GIL-holding functions or moving large chunks of data. This can cause timeouts and instability.
distributed.core - INFO - Event loop was unresponsive in Worker for 5.49s.  This is often caused by long-running GIL-holding functions or moving large chunks of data. This can cause timeouts and instability.
distributed.worker - ERROR - [Errno 122] Disk quota exceeded
Traceback (most recent call last):
  File "/home/ad/alberta/.conda/envs/perf-pangeo/lib/python3.6/site-packages/distributed/worker.py", line 2511, in execute
    data[k] = self.data[k]
  File "/home/ad/alberta/.conda/envs/perf-pangeo/lib/python3.6/site-packages/zict/buffer.py", line 78, in __getitem__
    return self.slow_to_fast(key)
  File "/home/ad/alberta/.conda/envs/perf-pangeo/lib/python3.6/site-packages/zict/buffer.py", line 69, in slow_to_fast
    self.fast[key] = value
  File "/home/ad/alberta/.conda/envs/perf-pangeo/lib/python3.6/site-packages/zict/lru.py", line 70, in __setitem__
    self.evict()
  File "/home/ad/alberta/.conda/envs/perf-pangeo/lib/python3.6/site-packages/zict/lru.py", line 89, in evict
    cb(k, v)
  File "/home/ad/alberta/.conda/envs/perf-pangeo/lib/python3.6/site-packages/zict/buffer.py", line 60, in fast_to_slow
    self.slow[key] = value
  File "/home/ad/alberta/.conda/envs/perf-pangeo/lib/python3.6/site-packages/zict/func.py", line 41, in __setitem__
    self.d[key] = self.dump(value)
  File "/home/ad/alberta/.conda/envs/perf-pangeo/lib/python3.6/site-packages/zict/file.py", line 84, in __setitem__
    f.write(value)
OSError: [Errno 122] Disk quota exceeded
tornado.application - ERROR - Exception in callback functools.partial(<bound method IOLoop._discard_future_result of <tornado.platform.asyncio.AsyncIOLoop object at 0x2b93969b30f0>>, <Task finished coro=<Worker.execute() done, defined at /home/ad/alberta/.conda/envs/perf-pangeo/lib/python3.6/site-packages/distributed/worker.py:2494> exception=OSError(122, 'Disk quota exceeded')>)
Traceback (most recent call last):
  File "/home/ad/alberta/.conda/envs/perf-pangeo/lib/python3.6/site-packages/tornado/ioloop.py", line 743, in _run_callback
    ret = callback()
  File "/home/ad/alberta/.conda/envs/perf-pangeo/lib/python3.6/site-packages/tornado/ioloop.py", line 767, in _discard_future_result
    future.result()
  File "/home/ad/alberta/.conda/envs/perf-pangeo/lib/python3.6/site-packages/distributed/worker.py", line 2511, in execute
    data[k] = self.data[k]
  File "/home/ad/alberta/.conda/envs/perf-pangeo/lib/python3.6/site-packages/zict/buffer.py", line 78, in __getitem__
    return self.slow_to_fast(key)
  File "/home/ad/alberta/.conda/envs/perf-pangeo/lib/python3.6/site-packages/zict/buffer.py", line 69, in slow_to_fast
    self.fast[key] = value
  File "/home/ad/alberta/.conda/envs/perf-pangeo/lib/python3.6/site-packages/zict/lru.py", line 70, in __setitem__
    self.evict()
  File "/home/ad/alberta/.conda/envs/perf-pangeo/lib/python3.6/site-packages/zict/lru.py", line 89, in evict
    cb(k, v)
  File "/home/ad/alberta/.conda/envs/perf-pangeo/lib/python3.6/site-packages/zict/buffer.py", line 60, in fast_to_slow
    self.slow[key] = value
  File "/home/ad/alberta/.conda/envs/perf-pangeo/lib/python3.6/site-packages/zict/func.py", line 41, in __setitem__
    self.d[key] = self.dump(value)
  File "/home/ad/alberta/.conda/envs/perf-pangeo/lib/python3.6/site-packages/zict/file.py", line 84, in __setitem__
    f.write(value)
OSError: [Errno 122] Disk quota exceeded
distributed.core - INFO - Event loop was unresponsive in Worker for 11.46s.  This is often caused by long-running GIL-holding functions or moving large chunks of data. This can cause timeouts and instability.
tornado.application - ERROR - Exception in callback functools.partial(<bound method IOLoop._discard_future_result of <tornado.platform.asyncio.AsyncIOLoop object at 0x2b93969b30f0>>, <Task finished coro=<Worker.memory_monitor() done, defined at /home/ad/alberta/.conda/envs/perf-pangeo/lib/python3.6/site-packages/distributed/worker.py:2611> exception=OSError(122, 'Disk quota exceeded')>)
Traceback (most recent call last):
  File "/home/ad/alberta/.conda/envs/perf-pangeo/lib/python3.6/site-packages/tornado/ioloop.py", line 743, in _run_callback
    ret = callback()
  File "/home/ad/alberta/.conda/envs/perf-pangeo/lib/python3.6/site-packages/tornado/ioloop.py", line 767, in _discard_future_result
    future.result()
  File "/home/ad/alberta/.conda/envs/perf-pangeo/lib/python3.6/site-packages/distributed/worker.py", line 2681, in memory_monitor
    k, v, weight = self.data.fast.evict()
  File "/home/ad/alberta/.conda/envs/perf-pangeo/lib/python3.6/site-packages/zict/lru.py", line 89, in evict
    cb(k, v)
  File "/home/ad/alberta/.conda/envs/perf-pangeo/lib/python3.6/site-packages/zict/buffer.py", line 60, in fast_to_slow
    self.slow[key] = value
  File "/home/ad/alberta/.conda/envs/perf-pangeo/lib/python3.6/site-packages/zict/func.py", line 41, in __setitem__
    self.d[key] = self.dump(value)
  File "/home/ad/alberta/.conda/envs/perf-pangeo/lib/python3.6/site-packages/zict/file.py", line 84, in __setitem__
    f.write(value)
OSError: [Errno 122] Disk quota exceeded
distributed.core - INFO - Event loop was unresponsive in Worker for 3.03s.  This is often caused by long-running GIL-holding functions or moving large chunks of data. This can cause timeouts and instability.
distributed.worker - INFO - Failed to put key in memory
Traceback (most recent call last):
  File "/home/ad/alberta/.conda/envs/perf-pangeo/lib/python3.6/site-packages/distributed/worker.py", line 1698, in transition_executing_done
    self.put_key_in_memory(key, value, transition=False)
  File "/home/ad/alberta/.conda/envs/perf-pangeo/lib/python3.6/site-packages/distributed/worker.py", line 1921, in put_key_in_memory
    self.data[key] = value
  File "/home/ad/alberta/.conda/envs/perf-pangeo/lib/python3.6/site-packages/zict/buffer.py", line 87, in __setitem__
    self.fast[key] = value
  File "/home/ad/alberta/.conda/envs/perf-pangeo/lib/python3.6/site-packages/zict/lru.py", line 70, in __setitem__
    self.evict()
  File "/home/ad/alberta/.conda/envs/perf-pangeo/lib/python3.6/site-packages/zict/lru.py", line 89, in evict
    cb(k, v)
  File "/home/ad/alberta/.conda/envs/perf-pangeo/lib/python3.6/site-packages/zict/buffer.py", line 60, in fast_to_slow
    self.slow[key] = value
  File "/home/ad/alberta/.conda/envs/perf-pangeo/lib/python3.6/site-packages/zict/func.py", line 41, in __setitem__
    self.d[key] = self.dump(value)
  File "/home/ad/alberta/.conda/envs/perf-pangeo/lib/python3.6/site-packages/zict/file.py", line 84, in __setitem__
    f.write(value)
OSError: [Errno 122] Disk quota exceeded
distributed.core - INFO - Event loop was unresponsive in Worker for 5.27s.  This is often caused by long-running GIL-holding functions or moving large chunks of data. This can cause timeouts and instability.
distributed.worker - ERROR - "('mean_chunk-2f7384593acde7879d1689441c7ac2ef', 1718, 0, 0)"
Traceback (most recent call last):
  File "/home/ad/alberta/.conda/envs/perf-pangeo/lib/python3.6/site-packages/distributed/worker.py", line 2511, in execute
    data[k] = self.data[k]
  File "/home/ad/alberta/.conda/envs/perf-pangeo/lib/python3.6/site-packages/zict/buffer.py", line 80, in __getitem__
    raise KeyError(key)
KeyError: "('mean_chunk-2f7384593acde7879d1689441c7ac2ef', 1718, 0, 0)"

During handling of the above exception, another exception occurred:

Traceback (most recent call last):
  File "/home/ad/alberta/.conda/envs/perf-pangeo/lib/python3.6/site-packages/distributed/worker.py", line 2515, in execute
    data[k] = Actor(type(self.actors[k]), self.address, k, self)
KeyError: "('mean_chunk-2f7384593acde7879d1689441c7ac2ef', 1718, 0, 0)"
tornado.application - ERROR - Exception in callback functools.partial(<bound method IOLoop._discard_future_result of <tornado.platform.asyncio.AsyncIOLoop object at 0x2b93969b30f0>>, <Task finished coro=<Worker.execute() done, defined at /home/ad/alberta/.conda/envs/perf-pangeo/lib/python3.6/site-packages/distributed/worker.py:2494> exception=KeyError("('mean_chunk-2f7384593acde7879d1689441c7ac2ef', 1718, 0, 0)",)>)
Traceback (most recent call last):
  File "/home/ad/alberta/.conda/envs/perf-pangeo/lib/python3.6/site-packages/distributed/worker.py", line 2511, in execute
    data[k] = self.data[k]
  File "/home/ad/alberta/.conda/envs/perf-pangeo/lib/python3.6/site-packages/zict/buffer.py", line 80, in __getitem__
    raise KeyError(key)
KeyError: "('mean_chunk-2f7384593acde7879d1689441c7ac2ef', 1718, 0, 0)"

During handling of the above exception, another exception occurred:

Traceback (most recent call last):
  File "/home/ad/alberta/.conda/envs/perf-pangeo/lib/python3.6/site-packages/tornado/ioloop.py", line 743, in _run_callback
    ret = callback()
  File "/home/ad/alberta/.conda/envs/perf-pangeo/lib/python3.6/site-packages/tornado/ioloop.py", line 767, in _discard_future_result
    future.result()
  File "/home/ad/alberta/.conda/envs/perf-pangeo/lib/python3.6/site-packages/distributed/worker.py", line 2515, in execute
    data[k] = Actor(type(self.actors[k]), self.address, k, self)
KeyError: "('mean_chunk-2f7384593acde7879d1689441c7ac2ef', 1718, 0, 0)"
distributed.core - INFO - Event loop was unresponsive in Worker for 6.42s.  This is often caused by long-running GIL-holding functions or moving large chunks of data. This can cause timeouts and instability.
distributed.core - INFO - Event loop was unresponsive in Worker for 3.10s.  This is often caused by long-running GIL-holding functions or moving large chunks of data. This can cause timeouts and instability.
distributed.nanny - WARNING - Worker exceeded 95% memory budget. Restarting
distributed.nanny - INFO - Worker process 9823 was killed by signal 15
/home/ad/alberta/.conda/envs/perf-pangeo/lib/python3.6/multiprocessing/semaphore_tracker.py:143: UserWarning: semaphore_tracker: There appear to be 1 leaked semaphores to clean up at shutdown
  len(cache))
distributed.nanny - WARNING - Restarting worker
distributed.worker - INFO -       Start worker at:   tcp://10.120.40.89:43047
distributed.worker - INFO -          Listening to:   tcp://10.120.40.89:43047
distributed.worker - INFO -          dashboard at:         10.120.40.89:43151
distributed.worker - INFO - Waiting to connect to:   tcp://10.120.43.21:43577
distributed.worker - INFO - -------------------------------------------------
distributed.worker - INFO -               Threads:                          1
distributed.worker - INFO -                Memory:                    8.00 GB
distributed.worker - INFO -       Local Directory: /home/ad/alberta/dask-worker-space/worker-dnh275xs
distributed.worker - INFO - -------------------------------------------------
distributed.worker - INFO -         Registered to:   tcp://10.120.43.21:43577
distributed.worker - INFO - -------------------------------------------------
distributed.core - INFO - Starting established connection
distributed.core - INFO - Event loop was unresponsive in Worker for 6.02s.  This is often caused by long-running GIL-holding functions or moving large chunks of data. This can cause timeouts and instability.
distributed.core - INFO - Event loop was unresponsive in Worker for 3.35s.  This is often caused by long-running GIL-holding functions or moving large chunks of data. This can cause timeouts and instability.
distributed.core - INFO - Event loop was unresponsive in Worker for 4.28s.  This is often caused by long-running GIL-holding functions or moving large chunks of data. This can cause timeouts and instability.
distributed.core - INFO - Event loop was unresponsive in Worker for 3.36s.  This is often caused by long-running GIL-holding functions or moving large chunks of data. This can cause timeouts and instability.
distributed.core - INFO - Event loop was unresponsive in Worker for 3.31s.  This is often caused by long-running GIL-holding functions or moving large chunks of data. This can cause timeouts and instability.
distributed.core - INFO - Event loop was unresponsive in Worker for 4.33s.  This is often caused by long-running GIL-holding functions or moving large chunks of data. This can cause timeouts and instability.
distributed.core - INFO - Event loop was unresponsive in Worker for 5.98s.  This is often caused by long-running GIL-holding functions or moving large chunks of data. This can cause timeouts and instability.
distributed.core - INFO - Event loop was unresponsive in Worker for 6.03s.  This is often caused by long-running GIL-holding functions or moving large chunks of data. This can cause timeouts and instability.
distributed.core - INFO - Event loop was unresponsive in Worker for 9.96s.  This is often caused by long-running GIL-holding functions or moving large chunks of data. This can cause timeouts and instability.
distributed.core - INFO - Event loop was unresponsive in Worker for 4.71s.  This is often caused by long-running GIL-holding functions or moving large chunks of data. This can cause timeouts and instability.
distributed.core - INFO - Event loop was unresponsive in Worker for 5.39s.  This is often caused by long-running GIL-holding functions or moving large chunks of data. This can cause timeouts and instability.
distributed.core - INFO - Event loop was unresponsive in Worker for 4.09s.  This is often caused by long-running GIL-holding functions or moving large chunks of data. This can cause timeouts and instability.
distributed.core - INFO - Event loop was unresponsive in Worker for 6.48s.  This is often caused by long-running GIL-holding functions or moving large chunks of data. This can cause timeouts and instability.
distributed.core - INFO - Event loop was unresponsive in Worker for 4.00s.  This is often caused by long-running GIL-holding functions or moving large chunks of data. This can cause timeouts and instability.
distributed.core - INFO - Event loop was unresponsive in Worker for 3.64s.  This is often caused by long-running GIL-holding functions or moving large chunks of data. This can cause timeouts and instability.
distributed.core - INFO - Event loop was unresponsive in Worker for 6.18s.  This is often caused by long-running GIL-holding functions or moving large chunks of data. This can cause timeouts and instability.
distributed.core - INFO - Event loop was unresponsive in Worker for 4.79s.  This is often caused by long-running GIL-holding functions or moving large chunks of data. This can cause timeouts and instability.
distributed.core - INFO - Event loop was unresponsive in Worker for 4.87s.  This is often caused by long-running GIL-holding functions or moving large chunks of data. This can cause timeouts and instability.
distributed.core - INFO - Event loop was unresponsive in Worker for 3.34s.  This is often caused by long-running GIL-holding functions or moving large chunks of data. This can cause timeouts and instability.
distributed.core - INFO - Event loop was unresponsive in Worker for 3.36s.  This is often caused by long-running GIL-holding functions or moving large chunks of data. This can cause timeouts and instability.
distributed.core - INFO - Event loop was unresponsive in Worker for 6.41s.  This is often caused by long-running GIL-holding functions or moving large chunks of data. This can cause timeouts and instability.
distributed.core - INFO - Event loop was unresponsive in Worker for 3.30s.  This is often caused by long-running GIL-holding functions or moving large chunks of data. This can cause timeouts and instability.
distributed.core - INFO - Event loop was unresponsive in Worker for 3.31s.  This is often caused by long-running GIL-holding functions or moving large chunks of data. This can cause timeouts and instability.
distributed.core - INFO - Event loop was unresponsive in Worker for 3.39s.  This is often caused by long-running GIL-holding functions or moving large chunks of data. This can cause timeouts and instability.
distributed.core - INFO - Event loop was unresponsive in Worker for 3.41s.  This is often caused by long-running GIL-holding functions or moving large chunks of data. This can cause timeouts and instability.
distributed.core - INFO - Event loop was unresponsive in Worker for 4.49s.  This is often caused by long-running GIL-holding functions or moving large chunks of data. This can cause timeouts and instability.
distributed.core - INFO - Event loop was unresponsive in Worker for 4.88s.  This is often caused by long-running GIL-holding functions or moving large chunks of data. This can cause timeouts and instability.
distributed.core - INFO - Event loop was unresponsive in Worker for 10.29s.  This is often caused by long-running GIL-holding functions or moving large chunks of data. This can cause timeouts and instability.
distributed.worker - INFO - Failed to put key in memory
Traceback (most recent call last):
  File "/home/ad/alberta/.conda/envs/perf-pangeo/lib/python3.6/site-packages/distributed/worker.py", line 1698, in transition_executing_done
    self.put_key_in_memory(key, value, transition=False)
  File "/home/ad/alberta/.conda/envs/perf-pangeo/lib/python3.6/site-packages/distributed/worker.py", line 1921, in put_key_in_memory
    self.data[key] = value
  File "/home/ad/alberta/.conda/envs/perf-pangeo/lib/python3.6/site-packages/zict/buffer.py", line 87, in __setitem__
    self.fast[key] = value
  File "/home/ad/alberta/.conda/envs/perf-pangeo/lib/python3.6/site-packages/zict/lru.py", line 70, in __setitem__
    self.evict()
  File "/home/ad/alberta/.conda/envs/perf-pangeo/lib/python3.6/site-packages/zict/lru.py", line 89, in evict
    cb(k, v)
  File "/home/ad/alberta/.conda/envs/perf-pangeo/lib/python3.6/site-packages/zict/buffer.py", line 60, in fast_to_slow
    self.slow[key] = value
  File "/home/ad/alberta/.conda/envs/perf-pangeo/lib/python3.6/site-packages/zict/func.py", line 41, in __setitem__
    self.d[key] = self.dump(value)
  File "/home/ad/alberta/.conda/envs/perf-pangeo/lib/python3.6/site-packages/zict/file.py", line 84, in __setitem__
    f.write(value)
OSError: [Errno 122] Disk quota exceeded
distributed.core - INFO - Event loop was unresponsive in Worker for 5.28s.  This is often caused by long-running GIL-holding functions or moving large chunks of data. This can cause timeouts and instability.
distributed.core - INFO - Event loop was unresponsive in Worker for 5.95s.  This is often caused by long-running GIL-holding functions or moving large chunks of data. This can cause timeouts and instability.
distributed.worker - ERROR - failed during get data with tcp://10.120.40.89:43047 -> tcp://10.120.40.89:45547
Traceback (most recent call last):
  File "/home/ad/alberta/.conda/envs/perf-pangeo/lib/python3.6/site-packages/distributed/comm/tcp.py", line 246, in write
    await future
tornado.iostream.StreamClosedError: Stream is closed

During handling of the above exception, another exception occurred:

Traceback (most recent call last):
  File "/home/ad/alberta/.conda/envs/perf-pangeo/lib/python3.6/site-packages/distributed/worker.py", line 1275, in get_data
    compressed = await comm.write(msg, serializers=serializers)
  File "/home/ad/alberta/.conda/envs/perf-pangeo/lib/python3.6/site-packages/distributed/comm/tcp.py", line 250, in write
    convert_stream_closed_error(self, e)
  File "/home/ad/alberta/.conda/envs/perf-pangeo/lib/python3.6/site-packages/distributed/comm/tcp.py", line 121, in convert_stream_closed_error
    raise CommClosedError("in %s: %s: %s" % (obj, exc.__class__.__name__, exc))
distributed.comm.core.CommClosedError: in <closed TCP>: BrokenPipeError: [Errno 32] Broken pipe
distributed.worker - ERROR - Worker stream died during communication: tcp://10.120.40.89:45547
Traceback (most recent call last):
  File "/home/ad/alberta/.conda/envs/perf-pangeo/lib/python3.6/site-packages/distributed/comm/tcp.py", line 193, in read
    n = await stream.read_into(frame)
tornado.iostream.StreamClosedError: Stream is closed

During handling of the above exception, another exception occurred:

Traceback (most recent call last):
  File "/home/ad/alberta/.conda/envs/perf-pangeo/lib/python3.6/site-packages/distributed/worker.py", line 1980, in gather_dep
    self.rpc, deps, worker, who=self.address
  File "/home/ad/alberta/.conda/envs/perf-pangeo/lib/python3.6/site-packages/distributed/worker.py", line 3251, in get_data_from_worker
    return await retry_operation(_get_data, operation="get_data_from_worker")
  File "/home/ad/alberta/.conda/envs/perf-pangeo/lib/python3.6/site-packages/distributed/utils_comm.py", line 390, in retry_operation
    operation=operation,
  File "/home/ad/alberta/.conda/envs/perf-pangeo/lib/python3.6/site-packages/distributed/utils_comm.py", line 370, in retry
    return await coro()
  File "/home/ad/alberta/.conda/envs/perf-pangeo/lib/python3.6/site-packages/distributed/worker.py", line 3238, in _get_data
    max_connections=max_connections,
  File "/home/ad/alberta/.conda/envs/perf-pangeo/lib/python3.6/site-packages/distributed/core.py", line 589, in send_recv
    response = await comm.read(deserializers=deserializers)
  File "/home/ad/alberta/.conda/envs/perf-pangeo/lib/python3.6/site-packages/distributed/comm/tcp.py", line 199, in read
    convert_stream_closed_error(self, e)
  File "/home/ad/alberta/.conda/envs/perf-pangeo/lib/python3.6/site-packages/distributed/comm/tcp.py", line 123, in convert_stream_closed_error
    raise CommClosedError("in %s: %s" % (obj, exc))
distributed.comm.core.CommClosedError: in <closed TCP>: Stream is closed
distributed.worker - INFO - Can't find dependencies for key ('mean_combine-partial-3cb5b01dd8ce18d0a3a7050d59647dae', 340, 0, 0)
distributed.core - INFO - Lost connection to 'tcp://10.120.40.89:46204': in <closed TCP>: BrokenPipeError: [Errno 32] Broken pipe
distributed.core - INFO - Event loop was unresponsive in Worker for 6.04s.  This is often caused by long-running GIL-holding functions or moving large chunks of data. This can cause timeouts and instability.
distributed.worker - INFO - Dependent not found: ('mean_chunk-2f7384593acde7879d1689441c7ac2ef', 1362, 0, 0) 0 .  Asking scheduler
distributed.dask_worker - INFO - Exiting on signal 15
distributed.nanny - INFO - Closing Nanny at 'tcp://10.120.40.89:35807'
/home/ad/alberta/.conda/envs/perf-pangeo/lib/python3.6/multiprocessing/semaphore_tracker.py:143: UserWarning: semaphore_tracker: There appear to be 6 leaked semaphores to clean up at shutdown
  len(cache))
/home/ad/alberta/.conda/envs/perf-pangeo/lib/python3.6/multiprocessing/semaphore_tracker.py:143: UserWarning: semaphore_tracker: There appear to be 1 leaked semaphores to clean up at shutdown
  len(cache))
